Workbook
Name aquimicos: [1]Aquimicos!$A$1:$T$769
Name assays: [2]Assays!$A$2:$E$50

Sheet 0. Portada
E6: BHP ESCONDIDA
E8: S179 QAQC Pruebas Laboratorio Jameson (BHP)
E11: RESULTADOS CONSOLIDADOS DE PRUEBAS
E12: EM-S179-PR-RP-001
C17: 1. Compósito
C18: 2. Datos LS2
C19: 3. Cinética Molienda
C20: 4. SKT Mineral actual y futuro
C21: 4.1 SKT Ro y Cleaner compósito
C22: 5. Análisis Granulométrico
C23: 6. Análisis Químico Cabeza
C24: 7. Mineralogía Modal Compósito
C25: 8. Liberación Compósito
C26: 9. Asociación Compósito
C27: 10. Test Cliclo Abierto
C28: 11. Casos
... C41: 21. QAQC Test Dilución
C44: Fecha | D44: Revision / Autor | E44: Revision / Jefe Esp. | F44: Cliente
C45: 45959 | D45: CL | E45: CM | F45: SR
C46: 45954 | D46: CL | E46: CM | F46: SR
C47: 45939 | D47: CL-IS | E47: MC | F47: SR
C48: 45931 | D48: CL | E48: MC | F48: SR
C49: 45922 | D49: CL | E49: MC | F49: SR

Sheet 1. Compósito
B3: Muestra ROM | C3: UGREC | D3: % representación en Plan FY28-FY35 | E3: Proporciones | F3: Compósito (ton) | G3: Cu (%)
B4: D | C4: 1 | D4: 0.43 | E4: 0.5 | F4: 50 | G4: ='6. Análisis Químico Cabeza'!$D$10 -> 0.64 | I4: * Preliminar, pendiente confirmación
B5: H | C5: 2
B6: G | C6: 2 | D6: 0.42 | E6: 0.292 | F6: 29.2 | G6: 0.85
B7: J | C7: 5 | D7: 0.15 | E7: 0.208 | F7: 20.8 | G7: 0.43
F8: Cu Calculado | G8: =+SUMPRODUCT(D4:D7,G4:G7) -> 0.6967
F9: Cu Analizado | G9: ='6. Análisis Químico Cabeza'!$D$7 -> 0.66
F10: Error | G10: =(G9-G8)/G9 -> -0.055606061

Sheet 2. Datos LS2
B3: Tabla 1. Tamaño y cantidad de celdas LS2 y MPP
B5: Etapa | E5: Celdas de Flotación LS2
E6: Tamaño | F6: Celdas/Fila | G6: Filas | H6: Volumen | I6: r/F. Primaria | K6: Planta Piloto AMINPRO
E7: m3 | H7: m3 | I7: % | K7: Etapa | L7: Volumen (l) | M7: Filas | N7: Celdas x Fila | O7: Total (l) | P7: r/F Primaria %
K8: Ro | L8: 72 | M8: 1 | N8: 6 | O8: =+N8*M8*L8 -> 432 | P8: =+O10/$O$8*100 -> 37.962963
B9: Flotación Primaria | E9: 300 | F9: 7 | G9: 7 | H9: =E9*F9*G9 -> 14700 | K9: 1 Cl | L9: 24.3 | M9: 1 | N9: 1 | O9: =+N9*M9*L9 -> 24.3
B10: Flotación Primera Limpieza | E10: 7 - 6 Columnas de 4,5 m de diametro | H10: =213.1*6*1 -> 1278.6 | K10: Scv | L10: 41 | M10: 1 | N10: 4 | O10: =+N10*M10*L10 -> 164
B11: Flotación Barrido | E11: 300 | F11: 7 | G11: 3 | H11: =E11*F11*G11 -> 6300 | I11: =H11/$H$9*100 -> 42.857143 | K11: Cl - Scv | L11: 13.7 | M11: 1 | N11: 1 | O11: =+N11*M11*L11 -> 13.7
B12: Flotación Segunda Limpieza | E12: 5 - 6 Columnas de 4,5 m de diametro | H12: =213.1*6*1 -> 1278.6
E14: * Según criterios de diseño originales
I16: r/F. Primaria | J16: Relación volumétrica de cada etapa respecto a la flotación primaria
I17: % | J17: debe ser igual a LS2
U25: =3.14*(0.0508^2)*3 -> 0.024309629 | V25: m3
U27: =3.14*((0.0254*1.5)^2)*3 -> 0.013674166 | V27: m3

Sheet 3. Cinética Molienda
B1: Compósito Global
B3: GRIND N° 01 | D3: 10 min | E3: Tiempo molienda: | F3: 10 | G3: min
B5: Mesh | C5: Pasante | D5: Masa | E5: Retenido | F5: Pasante | G5: Pass Swebrec
B6: ASTM | C6: [µm] | D6: [g] | E6: [%] | F6: [%] | G6: [%]
B7: 16 | C7: 1180 | D7: 0 | E7: 0 | F7: 100 | G7: 100
B8: 20 | C8: 850 | D8: 0 | E8: 0 | F8: 100 | G8: 100
B9: 30 | C9: 600 | D9: 1 | E9: 0.41339396 | F9: 99.586606 | G9: 100
B10: 40 | C10: 425 | D10: 6.4 | E10: 2.6457214 | F10: 96.940885 | G10: 98.21629
B11: 50 | C11: 300 | D11: 17.7 | E11: 7.3170732 | F11: 89.623811 | G11: 88.392635
B12: 70 | C12: 212 | D12: 28.9 | E12: 11.947086 | F12: 77.676726 | G12: 76.664455
B13: 100 | C13: 150 | D13: 33 | E13: 13.642001 | F13: 64.034725 | G13: 65.668973
B14: 140 | C14: 106 | D14: 20.4 | E14: 8.4332369 | F14: 55.601488 | G14: 56.140272
B15: 200 | C15: 75 | D15: 18.6 | E15: 7.6891277 | F15: 47.91236 | G15: 48.225285
B16: 270 | C16: 53 | D16: 13.7 | E16: 5.6634973 | F16: 42.248863 | G16: 41.68656
B17: 325 | C17: 45 | D17: 6.2 | E17: 2.5630426 | F17: 39.685821 | G17: 39.024153
B18: -325 | C18: 0 | D18: 96 | E18: 39.685821 | F18: 0 | G18: 0
B19: Total | D19: 241.9 | E19: 100
F21: P100 [µm] | G21: 486.63327
F22: P80 [µm] | G22: 234.02928
F23: P50 [µm] | G23: 81.534836
B26: GRIND N° 02 | D26: 20 min | E26: Tiempo molienda: | F26: 20 | G26: min
B28: Mesh | C28: Pasante | D28: Masa | E28: Retenido | F28: Pass Actual | G28: Pass Swebrec
B29: ASTM | C29: (µm) | D29: (gr) | E29: (%) | F29: (%) | G29: (%)
B30: 16 | C30: 1180 | D30: 0 | E30: 0 | F30: 100 | G30: 100
B31: 20 | C31: 850 | D31: 0 | E31: 0 | F31: 100 | G31: 100
B32: 30 | C32: 600 | D32: 0 | E32: 0 | F32: 100 | G32: 100
B33: 40 | C33: 425 | D33: 0 | E33: 0 | F33: 100 | G33: 100
B34: 50 | C34: 300 | D34: 0.7 | E34: 0.28782895 | F34: 99.712171 | G34: 100
B35: 70 | C35: 212 | D35: 3.6 | E35: 1.4802632 | F35: 98.231908 | G35: 99.125841
B36: 100 | C36: 150 | D36: 21.8 | E36: 8.9638158 | F36: 89.268092 | G36: 87.97233
B37: 140 | C37: 106 | D37: 36.3 | E37: 14.925987 | F37: 74.342105 | G37: 74.723178
B38: 200 | C38: 75 | D38: 31.1 | E38: 12.787829 | F38: 61.554276 | G38: 62.906411
B39: 270 | C39: 53 | D39: 19.5 | E39: 8.0180921 | F39: 53.536184 | G39: 53.098876
B40: 325 | C40: 45 | D40: 9.2 | E40: 3.7828947 | F40: 49.753289 | G40: 49.156342
B41: -325 | C41: 0 | D41: 121 | E41: 49.753289 | F41: -7.1054274e-15 | G41: 0
B42: Total | D42: 243.2 | E42: 100
F44: P100 [µm] | G44: 226.02976
F45: P80 [µm] | G45: 121.95433
F46: P50 [µm] | G46: 46.671301
B49: GRIND N° 03 | D49: 30 min | E49: Tiempo molienda: | F49: 30 | G49: min
...

Sheet 4. SKT Mineral actual y futuro 
A1: Mineral Futuro (en Aminpro)
AA3: P80 | AB3: pH | AC3: Cp
Y4: SKT Rougher | AA4: 173 | AB4: 10.2 | AC4: 29.662763
B6: SKT Rougher - Muestra Futuro | Y6: SKT Cleaner (P80 = 45 µm) | AA6: 42.927333 | AB6: 11.33 | AC6: 18.991733
D7: Cu | E7: Fe | F7: S | G7: Mo | I7: Rougher | J7: Cu-Sulf | K7: MoS2 | L7: FeS2 | M7: FeOX | N7: Gangue | Q7: P80 | R7: pH | S7: Cp
C8: F | D8: 0.66 | E8: 2.24 | F8: 2.13 | G8: 0.0115 | I8: Rmáx | J8: 88.465459 | K8: 76.053794 | L8: 81.032363 | M8: 41.529603 | N8: 36.781285 | Q8: 173 | R8: 10.2 | S8: 29.662763 | Y8: SKT Cleaner (P80 = 35 µm) | AA8: 35.829979 | AB8: 11.35 | AC8: 18.788299
C9: C1 | D9: 6.56 | E9: 14.4 | F9: 17.84 | G9: 0.0832 | I9: k | J9: 1.7377485 | K9: 1.2808731 | L9: 1.5036263 | M9: 0.068883861 | N9: 0.052183274
C10: C2 | D10: 3.11 | E10: 9.8 | F10: 11.42 | G10: 0.0645 | Y10: SKT Cleaner (P80 = 35 µm) | AA10: 22.222607 | AB10: 11.35 | AC10: 18.007227
C11: C3 | D11: 0.53 | E11: 2.64 | F11: 2.39 | G11: 0.0157
C12: C4 | D12: 0.34 | E12: 1.42 | F12: 0.64 | G12: 0.0056
C13: T | D13: 0.096 | E13: 0.99 | F13: 0.45 | G13: 0.0038
C14: Rec. Experimental | D14: 91.025485 | E14: 72.774516 | F14: 86.282227 | G14: 79.801195 | AB14: Cu | AC14: Fe | AD14: S | AE14: Mo
Y15: SKT Rougher | AA15: Rec. Experimental | AB15: 91.025485 | AC15: 72.774516 | AD15: 86.282227 | AE15: 79.801195
Y17: SKT Cleaner (P80 = 45 µm) | AB17: 93.295887 | AC17: 79.299856 | AD17: 80.610624 | AE17: 63.11264
B19: SKT Cleaner - Muestra Futuro (P80 = 45 µm) | Y19: SKT Cleaner (P80 = 35 µm) | AB19: 99.087393 | AC19: 80.097396 | AD19: 82.770695 | AE19: 88.984745
I20: Cleaner | J20: Cu-Sulf | K20: MoS2 | L20: FeS2 | M20: FeOX | N20: Gangue | Q20: P80 | R20: pH | S20: Cp
I21: Rmáx | J21: 85.887465 | K21: 31.221543 | L21: 48.716679 | M21: 84.667928 | N21: 57.679197 | Q21: 42.927333 | R21: 11.33 | S21: 18.991733 | Y21: SKT Cleaner (P80 = 35 µm) | AB21: 98.934891 | AC21: 83.128454 | AD21: 84.188527 | AE21: 90.788041
I22: k | J22: 3.2105682 | K22: 0.43983145 | L22: 3.0929313 | M22: 0.083033721 | N22: 0.012019753
C27: =C14 -> Rec. Experimental | D27: 93.295887 | E27: 79.299856 | F27: 80.610624 | G27: 63.11264
AA30: Rougher | AB30: Cu-Sulf | AC30: MoS2 | AD30: FeS2 | AE30: FeOX | AF30: Ganga
Y31: SKT Rougher | AA31: Rmáx | AB31: 88.465459 | AC31: 76.053794 | AD31: 81.032363 | AE31: 41.529603 | AF31: 36.781285
B32: SKT Cleaner - Muestra Futuro (P80 = 35 µm) | AA32: k | AB32: 1.7377485 | AC32: 1.2808731 | AD32: 1.5036263 | AE32: 0.068883861 | AF32: 0.052183274
J33: Cu-Sulf | K33: MoS2 | L33: FeS2 | M33: FeOX | N33: Gangue | Q33: P80 | R33: pH | S33: Cp | Y33: SKT Cleaner (P80 = 45 µm) | AA33: Rmáx | AB33: 85.887465 | AC33: 31.221543 | AD33: 48.716679 | AE33: 84.667928 | AF33: 57.679197
I34: Rmáx | J34: 96.26767 | K34: 78.563574 | L34: 52.070458 | M34: 76.385566 | N34: 37.078972 | Q34: 35.829979 | R34: 11.35 | S34: 18.788299 | AA34: k | AB34: 3.2105682 | AC34: 0.43983145 | AD34: 3.0929313 | AE34: 0.083033721 | AF34: 0.012019753
I35: k | J35: 2.4991764 | K35: 1.3939552 | L35: 1.6839816 | M35: 0.085135532 | N35: 0.43715987 | Y35: SKT Cleaner (P80 = 35 µm) | AA35: Rmáx | AB35: 96.26767 | AC35: 78.563574 | AD35: 52.070458 | AE35: 76.385566 | AF35: 37.078972
AA36: k | AB36: 2.4991764 | AC36: 1.3939552 | AD36: 1.6839816 | AE36: 0.085135532 | AF36: 0.43715987
Y37: SKT Cleaner (P80 = 35 µm) | AA37: Rmáx | AB37: 95.92863 | AC37: 80.255318 | AD37: 48.808362 | AE37: 92.677138 | AF37: 62.90547
AA38: k | AB38: 2.1056917 | AC38: 0.47840784 | AD38: 1.5826905 | AE38: 0.060908405 | AF38: 0.0062128734
C40: =C27 -> Rec. Experimental | D40: 99.087393 | E40: 80.097396 | F40: 82.770695 | G40: 88.984745
AA42: Pruebas | AB42: Cu | AC42: Fe | AD42: S | AE42: Mo
Y43: SKT Rougher | AA43: F | AB43: 0.66 | AC43: 2.24 | AD43: 2.13 | AE43: 0.0115
AA44: C1 | AB44: 6.56 | AC44: 14.4 | AD44: 17.84 | AE44: 0.0832
B45: SKT Cleaner - Muestra Futuro (P80 = 25 µm) | AA45: C2 | AB45: 3.11 | AC45: 9.8 | AD45: 11.42 | AE45: 0.0645
J46: Cu-Sulf | K46: MoS2 | L46: FeS2 | M46: FeOX | N46: Gangue | Q46: P80 | R46: pH | S46: Cp | AA46: C3 | AB46: 0.53 | AC46: 2.64 | AD46: 2.39 | AE46: 0.0157
I47: Rmáx | J47: 95.92863 | K47: 80.255318 | L47: 48.808362 | M47: 92.677138 | N47: 62.90547 | Q47: 22.222607 | R47: 11.35 | S47: 18.007227 | AA47: C4 | AB47: 0.34 | AC47: 1.42 | AD47: 0.64 | AE47: 0.0056
I48: k | J48: 2.1056917 | K48: 0.47840784 | L48: 1.5826905 | M48: 0.060908405 | N48: 0.0062128734 | AA48: T | AB48: 0.096 | AC48: 0.99 | AD48: 0.45 | AE48: 0.0038
AA49: Rec. Experimental | AB49: 91.025485 | AC49: 72.774516 | AD49: 86.282227 | AE49: 79.801195
C53: =C40 -> Rec. Experimental | D53: 98.934891 | E53: 83.128454 | F53: 84.188527 | G53: 90.788041
A60: Mineral Actual LS2
AA63: P80 | AB63: pH | AC63: Cp
...

Sheet 4.1 SKT Ro y Cleaner compósito
A2: SKT Rougher Compósito | BQ2: Análisis Granulométrico
BQ3: Malla | BR3: µm | BS3: Masa, gr | BT3: Ret. Parc. | BU3: Ret. Acum. | BV3: Pasante
BQ4: 50 | BR4: 300 | BS4: 5.5 | BT4: =BS4/$BS$14*100 -> 2.2764901 | BU4: =BT4 -> 2.2764901 | BV4: =100-BU4 -> 97.72351 | BX4: =IF(BV4=80,$BR4,IF(BV4>80,IF(BV5<80,$BR5*10^(LOG(80/BV5)*LOG($BR4/$BR5)/LOG(BV4/BV5)),0),0)) -> 0 | BY4: =IF(BV4=50,$BR4,IF(BV4>50,IF(BV5<50,$BR5*10^(LOG(50/BV5)*LOG($BR4/$BR5)/LOG(BV4/BV5)),0),0)) -> 0
BQ5: 70 | BR5: 212 | BS5: 13.8 | BT5: =BS5/$BS$14*100 -> 5.7119205 | BU5: =BU4+BT5 -> 7.9884106 | BV5: =100-BU5 -> 92.011589 | BX5: =IF(BV5=80,$BR5,IF(BV5>80,IF(BV6<80,$BR6*10^(LOG(80/BV6)*LOG($BR5/$BR6)/LOG(BV5/BV6)),0),0)) -> 159.96876 | BY5: =IF(BV5=50,$BR5,IF(BV5>50,IF(BV6<50,$BR6*10^(LOG(50/BV6)*LOG($BR5/$BR6)/LOG(BV5/BV6)),0),0)) -> 0
BQ6: 100 | BR6: 150 | BS6: 35.1 | BT6: =BS6/$BS$14*100 -> 14.528146 | BU6: =BU5+BT6 -> 22.516556 | BV6: =100-BU6 -> 77.483444 | BX6: =IF(BV6=80,$BR6,IF(BV6>80,IF(BV7<80,$BR7*10^(LOG(80/BV7)*LOG($BR6/$BR7)/LOG(BV6/BV7)),0),0)) -> 0 | BY6: =IF(BV6=50,$BR6,IF(BV6>50,IF(BV7<50,$BR7*10^(LOG(50/BV7)*LOG($BR6/$BR7)/LOG(BV6/BV7)),0),0)) -> 0
BQ7: 140 | BR7: 106 | BS7: 34.2 | BT7: =BS7/$BS$14*100 -> 14.155629 | BU7: =BU6+BT7 -> 36.672185 | BV7: =100-BU7 -> 63.327815 | BX7: =IF(BV7=80,$BR7,IF(BV7>80,IF(BV8<80,$BR8*10^(LOG(80/BV8)*LOG($BR7/$BR8)/LOG(BV7/BV8)),0),0)) -> 0 | BY7: =IF(BV7=50,$BR7,IF(BV7>50,IF(BV8<50,$BR8*10^(LOG(50/BV8)*LOG($BR7/$BR8)/LOG(BV7/BV8)),0),0)) -> 0
BQ8: 200 | BR8: 75 | BS8: 12.4 | BT8: =BS8/$BS$14*100 -> 5.1324503 | BU8: =BU7+BT8 -> 41.804636 | BV8: =100-BU8 -> 58.195364 | BX8: =IF(BV8=80,$BR8,IF(BV8>80,IF(BV9<80,$BR9*10^(LOG(80/BV9)*LOG($BR8/$BR9)/LOG(BV8/BV9)),0),0)) -> 0 | BY8: =IF(BV8=50,$BR8,IF(BV8>50,IF(BV9<50,$BR9*10^(LOG(50/BV9)*LOG($BR8/$BR9)/LOG(BV8/BV9)),0),0)) -> 0
E9: Reagents, g/T | BQ9: 270 | BR9: 53 | BS9: 15.8 | BT9: =BS9/$BS$14*100 -> 6.5397351 | BU9: =BU8+BT9 -> 48.344371 | BV9: =100-BU9 -> 51.655629 | BX9: =IF(BV9=80,$BR9,IF(BV9>80,IF(BV10<80,$BR10*10^(LOG(80/BV10)*LOG($BR9/$BR10)/LOG(BV9/BV10)),0),0)) -> 0 | BY9: =IF(BV9=50,$BR9,IF(BV9>50,IF(BV10<50,$BR10*10^(LOG(50/BV10)*LOG($BR9/$BR10)/LOG(BV9/BV10)),0),0)) -> 49.396909
B10: STAGE | C10: min:seg | D10: pH | E10: eH, mV | F10: CaO | G10: =G14 -> Matcol 715 | H10: =G15 -> FP 650 | I10: =G16 -> 0 | J10: =G17 -> 0 | K10: =G18 -> 0 | L10: =G19 -> 0 | N10: Wet Mass | O10: Dry Mass | P10: % Sol | BQ10: 325 | BR10: 45 | BS10: 9.1 | BT10: =BS10/$BS$14*100 -> 3.7665563 | BU10: =BU9+BT10 -> 52.110927 | BV10: =100-BU10 -> 47.889073 | BX10: =IF(BV10=80,$BR10,IF(BV10>80,IF(BV11<80,$BR11*10^(LOG(80/BV11)*LOG($BR10/$BR11)/LOG(BV10/BV11)),0),0)) -> 0 | BY10: =IF(BV10=50,$BR10,IF(BV10>50,IF(BV11<50,$BR11*10^(LOG(50/BV11)*LOG($BR10/$BR11)/LOG(BV10/BV11)),0),0)) -> 0
B11: Grind | C11: 16:47 | D11: 8.47 | E11: 141.1 | F11: 300 | G11: 28 | H11: 0 | N11: =O11/P11 -> 2573.5294 | O11: 1750 | P11: 0.68 | BQ11: 400 | BR11: 38 | BS11: 7.6 | BT11: =BS11/$BS$14*100 -> 3.1456954 | BU11: =BU10+BT11 -> 55.256623 | BV11: =100-BU11 -> 44.743377 | BX11: =IF(BV11=80,$BR11,IF(BV11>80,IF(BV12<80,$BR12*10^(LOG(80/BV12)*LOG($BR11/$BR12)/LOG(BV11/BV12)),0),0)) -> 0 | BY11: =IF(BV11=50,$BR11,IF(BV11>50,IF(BV12<50,$BR12*10^(LOG(50/BV12)*LOG($BR11/$BR12)/LOG(BV11/BV12)),0),0)) -> 0
BQ12: 500 | BR12: 25 | BS12: 12.1 | BT12: =BS12/$BS$14*100 -> 5.0082781 | BU12: =BU11+BT12 -> 60.264901 | BV12: =100-BU12 -> 39.735099 | BX12: =IF(BV12=80,$BR12,IF(BV12>80,IF(BV13<80,$BR13*10^(LOG(80/BV13)*LOG($BR12/$BR13)/LOG(BV12/BV13)),0),0)) -> 0 | BY12: =IF(BV12=50,$BR12,IF(BV12>50,IF(BV13<50,$BR13*10^(LOG(50/BV13)*LOG($BR12/$BR13)/LOG(BV12/BV13)),0),0)) -> 0
B13: Grinding Conditions | F13: Reagent Names/ID | BQ13: -500 | BR13: 0 | BS13: 96 | BT13: =BS13/$BS$14*100 -> 39.735099 | BU13: =BU12+BT13 -> 100 | BV13: =100-BU13 -> 0 | BX13: =IF(BV13=80,$BR13,IF(BV13>80,IF(BV14<80,$BR14*10^(LOG(80/BV14)*LOG($BR13/$BR14)/LOG(BV13/BV14)),0),0)) -> 0 | BY13: =IF(BV13=50,$BR13,IF(BV13>50,IF(BV14<50,$BR14*10^(LOG(50/BV14)*LOG($BR13/$BR14)/LOG(BV13/BV14)),0),0)) -> 0
C14: Mill Diameter [cm] | D14: 17.4 | F14: Reagent 1 | G14: Matcol 715 | H14: =G30 -> 28 | P14: =P20-BS14 -> 0 | BS14: =SUM(BS4:BS13) -> 241.6 | BT14: =SUM(BT4:BT13) -> 100 | BX14: =SUM(BX4:BX13) -> 159.96876 | BY14: =SUM(BY4:BY13) -> 49.396909
C15: Mill Length [cm] | D15: 22.3 | F15: Reagent 2 | G15: FP 650 | H15: =H30 -> 32 | N15: ASTM | O15: µm | P15: Mass (g) | Q15: % Mass
C16: Steel Charge [g] | D16: 9371 | F16: Reagent 3 | H16: =I30 -> 0 | M16: FEED | N16: 70 | O16: 212 | P16: =SUM(BS4:BS5) -> 19.3 | Q16: =+P16/$P$20*100 -> 7.9884106 | BR16: P80 | BS16: =BX14 -> 159.96876
C17: Mill Speed [RPM] | D17: 77 | F17: Reagent 4 | M17: Screens | N17: 140 | O17: 106 | P17: =SUM(BS6:BS7) -> 69.3 | Q17: =+P17/$P$20*100 -> 28.683775 | R17: 2 | AF17: 3 | AG17: 4 | AH17: 5 | AI17: 6 | AJ17: 7 | AK17: 8 | BR17: P50 | BS17: =BY14 -> 49.396909
C18: % solids [% m/m) | D18: =P11 -> 0.68 | F18: Reagent 5 | N18: 325 | O18: 45 | P18: =SUM(BS8:BS10) -> 37.3 | Q18: =+P18/$P$20*100 -> 15.438742 | R18: Tracers [%] | AF18: Adders [%] | AU18: Mineralogy [Qemscan / MLA / XRD]
F19: Reagent 6 | N19: pan | O19: 0 | P19: =SUM(BS11:BS13) -> 115.7 | Q19: =+P19/$P$20*100 -> 47.889073 | AF19: Cu | AG19: Fe | AH19: S | AI19: Mo | BJ19: Bandeja | BK19: Tara
N20: Feed Assay | P20: =SUM(P16:P19) -> 241.6 | Q20: =+P20/$P$20*100 -> 100 | R20: 0 | AF20: 0.66 | AG20: 2.24 | AH20: 2.13 | AI20: 0.0115 | AJ20: 0 | AK20: 0 | AL20: =+VLOOKUP($BQ26,aquimicos,AL$17,FALSE) -> #VALUE! | AM20: =+VLOOKUP($BQ26,aquimicos,AM$17,FALSE) -> #VALUE! | AN20: =+VLOOKUP($BQ26,aquimicos,AN$17,FALSE) -> #VALUE! | AO20: =+VLOOKUP($BQ26,aquimicos,AO$17,FALSE) -> #VALUE! | AP20: =+VLOOKUP($BQ26,aquimicos,AP$17,FALSE) -> #VALUE! | AQ20: =+VLOOKUP($BQ26,aquimicos,AQ$17,FALSE) -> #VALUE! | AR20: =+VLOOKUP($BQ26,aquimicos,AR$17,FALSE) -> #VALUE! | AS20: =+VLOOKUP($BQ26,aquimicos,AS$17,FALSE) -> #VALUE! | ... BI20: =+VLOOKUP($BQ26,aquimicos,BI$17,FALSE) -> #VALUE!
E22: Reactivos/reagents, g/t
B23: Stage | C23: Cum t,min | D23: =D10 -> pH | E23: =E10 -> eH, mV | F23: =F10 -> CaO | G23: =G10 -> Matcol 715 | H23: =H10 -> FP 650 | I23: =+G16 -> 0 | J23: =+G17 -> 0 | K23: =+G18 -> 0 | L23: =+G19 -> 0 | M23: Stage
N24: Wet | O24: Dry | P24: % Solids | Q24: Mass | R24: Tracers [g/t] | AF24: Adders [%] | AU24: Mineralogy [Qemscan / MLA / XRD]
B25: Conditioning 2 | C25: 1 | D25: 10.21 | E25: 66 | F25: =(H36*10%)/($O$34/1000000) -> 923.7342 | H25: 16 | N25: Mass | O25: Mass | P25: by mass | Q25: Dist (%) | R25: =R$19 -> 0 | S25: =S$19 -> 0 | T25: =T$19 -> 0 | U25: =U$19 -> 0 | V25: =V$19 -> 0 | W25: =W$19 -> 0 | X25: =X$19 -> 0 | Y25: =Y$19 -> 0 | ... BI25: =BI$19 -> 0 | BJ25: Bandeja | BK25: Tara | BO25: Bandeja | BP25: Peso pulpa | BQ25: Codigo Aminpro
B26: Flot 1 | C26: 0.75 | D26: 10.23 | E26: 58.8 | F26: =(H37*10%)/($O$34/1000000) -> 80.826742 | M26: Conc 1 | N26: =+BP27-BK26 -> 537.3 | O26: 114.1 | P26: =O26/N26*100 -> 21.235809 | Q26: =O26/$O$34*100 -> 6.5873795 | R26: 0 | AF26: 6.56 | AG26: 14.4 | AH26: 17.84 | AI26: 0.0832 | AJ26: 0 | AK26: 0 | BJ26: F161 | BK26: 385.8 | BO26: F | BQ26: SKT Rougher-F
B27: Flot 2 | C27: 2 | D27: 10.2 | E27: 65 | F27: =(H38*10%)/($O$34/1000000) -> 0 | M27: Conc 2 | N27: =+BP28-BK27 -> 394.7 | O27: 52.9 | P27: =O27/N27*100 -> 13.402584 | Q27: =O27/$O$34*100 -> 3.0540962 | R27: 0 | AF27: 3.11 | AG27: 9.8 | AH27: 11.42 | AI27: 0.0645 | AJ27: 0 | AK27: 0 | BJ27: F145 | BK27: 405.9 | BO27: C1 | BP27: 923.1 | BQ27: SKT Rougher-C1
B28: Flot 3 | C28: 8 | D28: 10.2 | E28: 66.9 | F28: =(H39*10%)/($O$34/1000000) -> 115.46677 | M28: Conc 3 | N28: =+BP29-BK28 -> 1642 | O28: 141.3 | P28: =O28/N28*100 -> 8.6053593 | Q28: =O28/$O$34*100 -> 8.1577276 | R28: 0 | AF28: 0.53 | AG28: 2.64 | AH28: 2.39 | AI28: 0.0157 | AJ28: 0 | AK28: 0 | BJ28: F012 | BK28: 399.3 | BO28: C2 | BP28: 800.6 | BQ28: SKT Rougher-C2
B29: Flot 4 | C29: 30 | D29: 10.22 | E29: 68.9 | F29: =(H40*10%)/($O$34/1000000) -> 173.20016 | H29: 16 | M29: Conc 4 | N29: =+BP30-BK29 -> 4488.4 | O29: 303.3 | P29: =O29/N29*100 -> 6.7574191 | Q29: =O29/$O$34*100 -> 17.510536 | R29: 0 | AF29: 0.34 | AG29: 1.42 | AH29: 0.64 | AI29: 0.0056 | AJ29: 0 | AK29: 0 | BJ29: B035 | BK29: 593.8 | BO29: C3 | BP29: 2041.3 | BQ29: SKT Rougher-C3
B30: Total | C30: =C29 -> 30 | F30: =+SUM(F24:F29,F11) -> 1593.2279 | G30: =+SUM(G24:G29,G11) -> 28 | H30: =+SUM(H24:H29,H11) -> 32 | I30: =+SUM(I24:I29,I11) -> 0 | J30: =+SUM(J24:J29,J11) -> 0 | K30: =+SUM(K24:K29,K11) -> 0 | L30: =+SUM(L24:L29,L11) -> 0 | M30: Tot Conc | N30: =SUM(N26:N29) -> 7062.4 | O30: =SUM(O26:O29) -> 611.6 | P30: =O30/N30*100 -> 8.6599456 | Q30: =O30/$O$34*100 -> 35.30974 | R30: 0 | S30: =IF(S19=0,0,SUMPRODUCT(S26:S29,$Q$26:$Q$29)/$Q$30) -> 0 | T30: =IF(T19=0,0,SUMPRODUCT(T26:T29,$Q$26:$Q$29)/$Q$30) -> 0 | U30: =IF(U19=0,0,SUMPRODUCT(U26:U29,$Q$26:$Q$29)/$Q$30) -> 0 | V30: =IF(V19=0,0,SUMPRODUCT(V26:V29,$Q$26:$Q$29)/$Q$30) -> 0 | W30: =IF(W19=0,0,SUMPRODUCT(W26:W29,$Q$26:$Q$29)/$Q$30) -> 0 | X30: =IF(X19=0,0,SUMPRODUCT(X26:X29,$Q$26:$Q$29)/$Q$30) -> 0 | Y30: =IF(Y19=0,0,SUMPRODUCT(Y26:Y29,$Q$26:$Q$29)/$Q$30) -> 0 | Z30: =IF(Z19=0,0,SUMPRODUCT(Z26:Z29,$Q$26:$Q$29)/$Q$30) -> 0 | ... AE30: =IF(AE19=0,0,SUMPRODUCT(AE26:AE29,$Q$26:$Q$29)/$Q$30) -> 0 | AF30: 1.7838882 | AG30: 4.8482309 | AH30: 5.1855477 | AI30: 0.027505003 | AJ30: 0 | AK30: 0 | AL30: =IF(AL19=0,0,SUMPRODUCT(AL26:AL29,$Q$26:$Q$29)/$Q$30) -> 0 | AM30: =IF(AM19=0,0,SUMPRODUCT(AM26:AM29,$Q$26:$Q$29)/$Q$30) -> 0 | AN30: =IF(AN19=0,0,SUMPRODUCT(AN26:AN29,$Q$26:$Q$29)/$Q$30) -> 0 | AO30: =IF(AO19=0,0,SUMPRODUCT(AO26:AO29,$Q$26:$Q$29)/$Q$30) -> 0 | AP30: =IF(AP19=0,0,SUMPRODUCT(AP26:AP29,$Q$26:$Q$29)/$Q$30) -> 0 | AQ30: =IF(AQ19=0,0,SUMPRODUCT(AQ26:AQ29,$Q$26:$Q$29)/$Q$30) -> 0 | AR30: =IF(AR19=0,0,SUMPRODUCT(AR26:AR29,$Q$26:$Q$29)/$Q$30) -> 0 | AS30: =IF(AS19=0,0,SUMPRODUCT(AS26:AS29,$Q$26:$Q$29)/$Q$30) -> 0 | ... BI30: =IF(BI19=0,0,SUMPRODUCT(BI26:BI29,$Q$26:$Q$29)/$Q$30) -> 0 | BO30: C4 | BP30: 5082.2 | BQ30: SKT Rougher-C4
B31: Tail | D31: 10.22 | E31: 66.8 | M31: Tail | N31: =+BP31-BK31 -> 5763.3 | O31: 1120.5 | P31: =O31/(O31+D35*1000-O31/4.2)*100 -> 19.995666 | Q31: =O31/$O$34*100 -> 64.69026 | R31: 0 | S31: =IF(S19=0,0,AVERAGE(S32:S33)) -> 0 | T31: =IF(T19=0,0,AVERAGE(T32:T33)) -> 0 | U31: =IF(U19=0,0,AVERAGE(U32:U33)) -> 0 | V31: =IF(V19=0,0,AVERAGE(V32:V33)) -> 0 | W31: =IF(W19=0,0,AVERAGE(W32:W33)) -> 0 | X31: =IF(X19=0,0,AVERAGE(X32:X33)) -> 0 | Y31: =IF(Y19=0,0,AVERAGE(Y32:Y33)) -> 0 | Z31: =IF(Z19=0,0,AVERAGE(Z32:Z33)) -> 0 | ... AE31: =IF(AE19=0,0,AVERAGE(AE32:AE33)) -> 0 | AF31: 0.096 | AG31: 0.99 | AH31: 0.45 | AI31: 0.0038 | AJ31: 0 | AK31: 0 | AL31: =IF(AL19=0,0,AVERAGE(AL32:AL33)) -> 0 | AM31: =IF(AM19=0,0,AVERAGE(AM32:AM33)) -> 0 | AN31: =IF(AN19=0,0,AVERAGE(AN32:AN33)) -> 0 | AO31: =IF(AO19=0,0,AVERAGE(AO32:AO33)) -> 0 | AP31: =IF(AP19=0,0,AVERAGE(AP32:AP33)) -> 0 | AQ31: =IF(AQ19=0,0,AVERAGE(AQ32:AQ33)) -> 0 | AR31: =IF(AR19=0,0,AVERAGE(AR32:AR33)) -> 0 | AS31: =IF(AS19=0,0,AVERAGE(AS32:AS33)) -> 0 | ... BI31: =IF(BI19=0,0,AVERAGE(BI32:BI33)) -> 0 | BJ31: C-2 | BK31: 1457.5 | BO31: T | BP31: 7220.8 | BQ31: SKT Rougher-T
M32: Tail1 | R32: 0 | AF32: 0.096 | AG32: 0.99 | AH32: 0.45 | AI32: 0.0038 | AJ32: 0 | AK32: 0
H33: CAL 10% | I33: NaHS | M33: Tail2
B34: Flotation Cell | H34: mL | I34: mL | M34: Calc Feed | N34: =SUM(N30:N31) -> 12825.7 | O34: =SUM(O30:O31) -> 1732.1 | P34: =O34/(O34+D35*1000-O34/4.2)*100 -> 28.536853 | Q34: =O34/$O$34*100 -> 100 | R34: =IF(R19=0,0,SUMPRODUCT(R30:R31,$Q$30:$Q$31)/$Q$34) -> 0 | S34: =IF(S19=0,0,SUMPRODUCT(S30:S31,$Q$30:$Q$31)/$Q$34) -> 0 | T34: =IF(T19=0,0,SUMPRODUCT(T30:T31,$Q$30:$Q$31)/$Q$34) -> 0 | U34: =IF(U19=0,0,SUMPRODUCT(U30:U31,$Q$30:$Q$31)/$Q$34) -> 0 | V34: =IF(V19=0,0,SUMPRODUCT(V30:V31,$Q$30:$Q$31)/$Q$34) -> 0 | W34: =IF(W19=0,0,SUMPRODUCT(W30:W31,$Q$30:$Q$31)/$Q$34) -> 0 | X34: =IF(X19=0,0,SUMPRODUCT(X30:X31,$Q$30:$Q$31)/$Q$34) -> 0 | Y34: =IF(Y19=0,0,SUMPRODUCT(Y30:Y31,$Q$30:$Q$31)/$Q$34) -> 0 | ... AE34: =IF(AE19=0,0,SUMPRODUCT(AE30:AE31,$Q$30:$Q$31)/$Q$34) -> 0 | AF34: 0.69198892 | AG34: 2.3523313 | AH34: 2.1221096 | AI34: 0.012170175 | AJ34: 0 | AK34: 0 | AL34: =IF(AL19=0,0,SUMPRODUCT(AL30:AL31,$Q$30:$Q$31)/$Q$34) -> 0 | AM34: =IF(AM19=0,0,SUMPRODUCT(AM30:AM31,$Q$30:$Q$31)/$Q$34) -> 0 | AN34: =IF(AN19=0,0,SUMPRODUCT(AN30:AN31,$Q$30:$Q$31)/$Q$34) -> 0 | AO34: =IF(AO19=0,0,SUMPRODUCT(AO30:AO31,$Q$30:$Q$31)/$Q$34) -> 0 | AP34: =IF(AP19=0,0,SUMPRODUCT(AP30:AP31,$Q$30:$Q$31)/$Q$34) -> 0 | AQ34: =IF(AQ19=0,0,SUMPRODUCT(AQ30:AQ31,$Q$30:$Q$31)/$Q$34) -> 0 | AR34: =IF(AR19=0,0,SUMPRODUCT(AR30:AR31,$Q$30:$Q$31)/$Q$34) -> 0 | AS34: =IF(AS19=0,0,SUMPRODUCT(AS30:AS31,$Q$30:$Q$31)/$Q$34) -> 0 | ... BI34: =IF(BI19=0,0,SUMPRODUCT(BI30:BI31,$Q$30:$Q$31)/$Q$34) -> 0
C35: Effective Volume [L] | D35: 4.75 | P35: Error | R35: =IF(R19=0,0,ABS(R34-R20)/R20*100) -> 0 | S35: =IF(S19=0,0,ABS(S34-S20)/S20*100) -> 0 | T35: =IF(T19=0,0,ABS(T34-T20)/T20*100) -> 0 | U35: =IF(U19=0,0,ABS(U34-U20)/U20*100) -> 0 | V35: =IF(V19=0,0,ABS(V34-V20)/V20*100) -> 0 | W35: =IF(W19=0,0,ABS(W34-W20)/W20*100) -> 0 | X35: =IF(X19=0,0,ABS(X34-X20)/X20*100) -> 0 | Y35: =IF(Y19=0,0,ABS(Y34-Y20)/Y20*100) -> 0 | ... AE35: =IF(AE19=0,0,ABS(AE34-AE20)/AE20*100) -> 0 | AF35: 4.8468053 | AG35: 5.014789 | AH35: 0.37044235 | AI35: 5.8276081 | AJ35: 0 | AK35: 0 | AL35: =IF(AL19=0,0,ABS(AL34-AL20)/AL20*100) -> 0 | AM35: =IF(AM19=0,0,ABS(AM34-AM20)/AM20*100) -> 0 | AN35: =IF(AN19=0,0,ABS(AN34-AN20)/AN20*100) -> 0 | AO35: =IF(AO19=0,0,ABS(AO34-AO20)/AO20*100) -> 0 | AP35: =IF(AP19=0,0,ABS(AP34-AP20)/AP20*100) -> 0 | AQ35: =IF(AQ19=0,0,ABS(AQ34-AQ20)/AQ20*100) -> 0 | AR35: =IF(AR19=0,0,ABS(AR34-AR20)/AR20*100) -> 0 | AS35: =IF(AS19=0,0,ABS(AS34-AS20)/AS20*100) -> 0 | ... BI35: =IF(BI19=0,0,ABS(BI34-BI20)/BI20*100) -> 0
C36: Cell Area [m2] | D36: 0.029 | G36: Acond | H36: 16
C37: N2 [l/min] | D37: 8 | G37: C1 | H37: 1.4
C38: Jg [cm/sec] | D38: =+((D37/60000)/D36)*100 -> 0.45977011 | G38: C2 | H38: 0 | AF38: Recovery (Preliminary) | AU38: Recovery (Preliminary)
C39: Impeller Diameter [cm] | D39: 7.3 | G39: C3 | H39: 2 | O39: Time | P39: Water | Q39: Mass | R39: =R$19 -> 0 | S39: =S$19 -> 0 | T39: =T$19 -> 0 | U39: =U$19 -> 0 | V39: =V$19 -> 0 | W39: =W$19 -> 0 | X39: =X$19 -> 0 | Y39: =Y$19 -> 0 | ... BI39: =BI$19 -> 0
C40: Rotational Velocity [rpm] | D40: 1200 | G40: C4 | H40: 3 | O40: 0 | Q40: 0 | R40: 0 | S40: 0 | T40: 0 | U40: 0 | V40: 0 | W40: 0 | X40: 0 | Y40: 0 | Z40: 0 | AA40: 0 | AB40: 0 | AC40: 0 | AD40: 0 | AE40: 0 | AF40: 0 | AG40: 0 | AH40: 0 | AI40: 0 | AJ40: 0 | AK40: 0 | AL40: 0 | AM40: 0 | AN40: 0 | AO40: 0 | AP40: 0 | AQ40: 0 | AR40: 0 | AS40: 0 | AT40: 0 | AU40: 0 | AV40: 0 | AW40: 0 | AX40: 0 | AY40: 0 | AZ40: 0 | BA40: 0 | BB40: 0 | BC40: 0 | BD40: 0 | BE40: 0 | BF40: 0 | BG40: 0 | BH40: 0 | BI40: 0
C41: Tip Speed [m/sec] | D41: =D39*PI()*D40/100/60 -> 4.5867253 | O41: =C26 -> 0.75 | Q41: =Q26 -> 6.5873795 | R41: =IF(R$39=0,0,R40+R26*$Q26/(R$34*$Q$34)*100) -> 0 | S41: =IF(S$39=0,0,S40+S26*$Q26/(S$34*$Q$34)*100) -> 0 | T41: =IF(T$39=0,0,T40+T26*$Q26/(T$34*$Q$34)*100) -> 0 | U41: =IF(U$39=0,0,U40+U26*$Q26/(U$34*$Q$34)*100) -> 0 | V41: =IF(V$39=0,0,V40+V26*$Q26/(V$34*$Q$34)*100) -> 0 | W41: =IF(W$39=0,0,W40+W26*$Q26/(W$34*$Q$34)*100) -> 0 | X41: =IF(X$39=0,0,X40+X26*$Q26/(X$34*$Q$34)*100) -> 0 | Y41: =IF(Y$39=0,0,Y40+Y26*$Q26/(Y$34*$Q$34)*100) -> 0 | ... BI41: =IF(BI$39=0,0,BI40+BI26*$Q26/(BI$34*$Q$34)*100) -> 0
O42: =C27 -> 2 | Q42: =Q27+Q41 -> 9.6414757 | R42: =IF(R$39=0,0,R41+R27*$Q27/(R$34*$Q$34)*100) -> 0 | S42: =IF(S$39=0,0,S41+S27*$Q27/(S$34*$Q$34)*100) -> 0 | T42: =IF(T$39=0,0,T41+T27*$Q27/(T$34*$Q$34)*100) -> 0 | U42: =IF(U$39=0,0,U41+U27*$Q27/(U$34*$Q$34)*100) -> 0 | V42: =IF(V$39=0,0,V41+V27*$Q27/(V$34*$Q$34)*100) -> 0 | W42: =IF(W$39=0,0,W41+W27*$Q27/(W$34*$Q$34)*100) -> 0 | X42: =IF(X$39=0,0,X41+X27*$Q27/(X$34*$Q$34)*100) -> 0 | Y42: =IF(Y$39=0,0,Y41+Y27*$Q27/(Y$34*$Q$34)*100) -> 0 | ... BI42: =IF(BI$39=0,0,BI41+BI27*$Q27/(BI$34*$Q$34)*100) -> 0
...

Sheet 5. Análisis Granulométrico
B2: Granulometría Alimentación Rougher | F2: Posterior a Molienda
B4: Granulometría Planta Laguna Seca 2
B5: Mesh | C5: Size | D5: Pass
B6: 28 | C6: 600 | D6: 100 | E6: 100
B7: 35 | C7: 425 | D7: 99.770965 | E7: 100
B8: 48 | C8: 300 | D8: 95.978405 | E8: 96.166709
B9: 65 | C9: 212 | D9: 87.593977 | E9: 87.202155
B10: 100 | C10: 150 | D10: 77.09963 | E10: 77.319972
B11: 150 | C11: 106 | D11: 67.829271 | E11: 67.90815
B12: 200 | C12: 75 | D12: 59.522314 | E12: 59.565628
B13: 270 | C13: 53 | D13: 52.457382 | E13: 52.339267
B14: Ciclón 1 | C14: 41.91975 | D14: 50.973497 | E14: 48.073394
B15: Ciclón 2 | C15: 31.43975 | D15: 46.790822 | E15: 43.450043
B16: Ciclón 3 | C16: 21.91275 | D16: 40.510177 | E16: 38.47719
B17: Ciclón 4 | C17: 15.2455 | D17: 35.227157 | E17: 34.261866
B18: Ciclón 5 | C18: 10.48125 | D18: 32.247641 | E18: 30.583952
D20: P100 | E20: 388.8786
D21: P80 | E21: 164.82011 | F21: =+_xlfn.FORECAST.LINEAR(80,C9:C10,E9:E10) -> 166.81427
D22: P50 | E22: 46.754148 | F22: =+_xlfn.FORECAST.LINEAR(50,C13:C14,E13:E14) -> 46.923948
F23: =+_xlfn.FORECAST.LINEAR(25,C17:C18,E17:E18) -> 3.2479802
E24: =SUMXMY2(D6:D13,E6:E13) -> 0.31203986
B27: Granulometría Lab Aminpro
B28: Mesh | C28: Size | D28: Pass
B29: 20 | C29: 850 | D29: 100 | E29: 100
B30: 30 | C30: 600 | D30: 100 | E30: 100
B31: 40 | C31: 425 | D31: 100 | E31: 100
B32: 50 | C32: 300 | D32: 99.160906 | E32: 99.160933 | I32: Lab es más desfavorabole porque tiene más gruesos. Ro flota intermedios
B33: 70 | C33: 212 | D33: 89.221289 | E33: 89.221324
B34: 100 | C34: 150 | D34: 76.901561 | E34: 76.901591
B35: 140 | C35: 106 | D35: 65.389052 | E35: 65.389077
B36: 200 | C36: 75 | D36: 55.627129 | E36: 55.627152
B37: 270 | C37: 53 | D37: 47.565688 | E37: 47.565711
B38: 325 | C38: 45 | D38: 44.303198 | E38: 44.303222
B39: 400 | C39: 38 | D39: 41.249688 | E39: 41.249711
D41: P100 | E41: 322.59784
D42: P80 | E42: 163.69212 | F42: =+_xlfn.FORECAST.LINEAR(80,C33:C34,E33:E34) -> 165.59298
D43: P50 | E43: 59.310478 | F43: =+_xlfn.FORECAST.LINEAR(50,C37:C38,E37:E38) -> 58.969157
E44: =SUMXMY2(D29:D39,E29:E39) -> 5.7417681e-09 | F44: =+_xlfn.FORECAST.LINEAR(25,C38:C39,E38:E39) -> 0.74846087

Sheet 6. Análisis Químico Cabeza
B2: Análisis Químico Cabeza
D4: Cu | E4: Fe | F4: Mo | G4: Cu sol | H4: S | I4: Ins
D5: % | E5: % | F5: G/T | G5: % | H5: % | I5: %
B6: N° | C6: ID Muestra | D6: CAA11D | E6: CAA11D | F6: CAA13F | G6: CAA09V | H6: LEC010B | I6: CLA020V | J6: ICP
B7: 001 | C7: Alimentación Compósito Global | D7: 0.66 | E7: 2.24 | F7: 115 | G7: 0.054 | H7: 2.13 | I7: 86.92 | J7: Pendiente
B8: 002 | C8: Muestra J | D8: 0.43 | E8: 3.37 | F8: 78 | G8: 0.028 | H8: 0.92 | I8: 87.09 | J8: Pendiente
B9: 003 | C9: Muestra G | D9: 0.85 | E9: 2.5 | F9: 203 | G9: 0.034 | H9: 3 | I9: 87.03 | J9: Pendiente
B10: 004 | C10: Muestra H | D10: 0.64 | E10: Pendiente | F10: Pendiente | G10: Pendiente | H10: Pendiente | I10: Pendiente | J10: Pendiente
B11: 005 | C11: Muestra D | E11: Pendiente | F11: Pendiente | G11: Pendiente | H11: Pendiente | I11: Pendiente | J11: Pendiente
C14: AQ por confirmar

Sheet 7. Mineralogía Modal Comp
B2: Mineralogía
C4: COMPÓSITO GLOBAL
B5: Cuarzo | C5: 56.12
B6: Muscovita/illita | C6: 32.208
B7: Plagioclasa | C7: 3.632
B8: Pirita | C8: 2.69
B9: Arcillas Al | C9: 1.354
B10: Clorita | C10: 1.311
B11: Calcopirita | C11: 1.239
B12: Hematita/Magnetita | C12: 0.282
B13: Alunita | C13: 0.196
B14: Biotita/flogopita | C14: 0.15
B15: Ilmenita | C15: 0.122
B16: Rutilo/anatase | C16: 0.121
... B32: Otros | C32: 0.003
C34: =SUM(C5:C32) -> 99.998
B39: Ocurrencia
B40: Menas | C40: COMPÓSITO GLOBAL
B41: Calcopirita | C41: 67.2431
B42: Calcosina/digenita | C42: 12.9536
B43: Covelina | C43: 9.9658
B44: Bornita | C44: 9.0529
B45: Enargita/Tennantita | C45: 0.7501
B46: Atacamita | C46: 0.0341
B47: Otros | C47: 0.0004
C48: =SUM(C41:C47) -> 100
B51: P80 | C51: 176 um

Sheet 8. Liberación Comp
B2: Liberación mineral
B4: Rangos Ampliados
B5: Rango | C5: COMPÓSITO GLOBAL
C6: Calcopirita | D6: Calcosina/digenita | E6: Covelina | F6: Bornita | G6: Enargita/Tennantita | H6: Molibdenita | I6: Pirita
B7: >90% | C7: 41.2431 | D7: 69.7479 | E7: 52.2914 | F7: 30.6622 | G7: 22.8039 | H7: 100 | I7: 63.5158
B8: 80%-90% | C8: 3.0791 | D8: 0 | E8: 14.2186 | F8: 0 | G8: 0 | H8: 0 | I8: 17.1462
B9: 70%-80% | C9: 9.6373 | D9: 0 | E9: 9.2832 | F9: 0 | G9: 0 | H9: 0 | I9: 5.3362
B10: 60%-70% | C10: 0.5317 | D10: 0 | E10: 3.8778 | F10: 0 | G10: 0 | H10: 0 | I10: 1.4243
B11: 50%-60% | C11: 1.2066 | D11: 2.8011 | E11: 0 | F11: 0 | G11: 0 | H11: 0 | I11: 1.6492
B12: 40%-50% | C12: 4.2967 | D12: 0.9804 | E12: 9.1657 | F12: 8.7108 | G12: 1.331 | H12: 0 | I12: 2.9346
B13: 30%-40% | C13: 2.2057 | D13: 0 | E13: 0 | F13: 21.6187 | G13: 11.7125 | H13: 0 | I13: 0.624
B14: 20%-30% | C14: 5.1082 | D14: 11.0644 | E14: 0.235 | F14: 10.1506 | G14: 3.9929 | H14: 0 | I14: 1.2254
B15: 10%-20% | C15: 17.7918 | D15: 0.2801 | E15: 7.168 | F15: 11.8087 | G15: 7.9858 | H15: 0 | I15: 3.4656
B16: <10% | C16: 14.8999 | D16: 15.1261 | E16: 3.7603 | F16: 17.049 | G16: 52.1739 | H16: 0 | I16: 2.6786
C19: =+SUM(C7:C16) -> 100.0001 | D19: =+SUM(D7:D16) -> 100 | E19: =+SUM(E7:E16) -> 100 | F19: =+SUM(F7:F16) -> 100 | G19: =+SUM(G7:G16) -> 100 | H19: =+SUM(H7:H16) -> 100 | I19: =+SUM(I7:I16) -> 99.9999

Sheet 9. Asociación comp
B2: Asociación mineral
B4: Sample / Grupo Mineral | C4: Feldespato K | D4: Muscovita/illita | E4: Arcillas Al | F4: Calcita | G4: Plagioclasa | H4: Piroxeno | I4: Ankerita/Siderita | J4: Hematita/Magnetita | K4: Galena | L4: Anfibol | M4: Biotita/flogopita | N4: Clorita | O4: Bornita | P4: Calcosina/digenita | Q4: Enargita/Tennantita | R4: Alunita | S4: Molibdenita | T4: Apatito | U4: Esfalerita | V4: Ilmenita | W4: Calcopirita | X4: Cuarzo | Y4: Rutilo/anatase | Z4: Pirita | AA4: Covelina
B5: COMPÓSITO GLOBAL
B6: Partículas libres | C6: 9.69 | D6: 24.95 | E6: 14.4 | F6: 14.29 | G6: 14.42 | H6: 0.23 | I6: 91.8 | J6: 28.19 | K6: 0 | L6: 2.1 | M6: 12.21 | N6: 10.2 | O6: 17.79 | P6: 44.54 | Q6: 22.8 | R6: 44.03 | S6: 100 | T6: 30.26 | U6: 0 | V6: 10.39 | W6: 30.11 | X6: 24.51 | Y6: 30.76 | Z6: 32.73 | AA6: 52.29
B7: Parículas binarias | C7: 2.18 | D7: 46.03 | E7: 19.21 | F7: 0 | G7: 12.38 | H7: 3.95 | I7: 8.2 | J7: 19.87 | K7: 0 | L7: 5.92 | M7: 4.85 | N7: 6.41 | O7: 15.16 | P7: 29.97 | Q7: 7.99 | R7: 22.35 | S7: 0 | T7: 11.11 | U7: 0 | V7: 4.03 | W7: 28.18 | X7: 52.19 | Y7: 28.46 | Z7: 34.5 | AA7: 8.34
B8: Feldespato K | D8: 0 | E8: 0.03 | F8: 0 | G8: 0 | H8: 0 | I8: 0 | J8: 0 | K8: 0 | L8: 0 | M8: 0 | N8: 0 | O8: 0 | P8: 0 | Q8: 0 | R8: 0 | S8: 0 | T8: 0 | U8: 0 | V8: 0 | W8: 0 | X8: 0.01 | Y8: 0 | Z8: 0 | AA8: 0
B9: Muscovita/illita | C9: 0 | E9: 10.6 | F9: 0 | G9: 9.5 | H9: 0.58 | I9: 8.2 | J9: 10.7 | K9: 0 | L9: 0 | M9: 0.9 | N9: 3.79 | O9: 0 | P9: 10.78 | Q9: 0 | R9: 14.94 | S9: 0 | T9: 7.52 | U9: 0 | V9: 1.03 | W9: 24.77 | X9: 50.33 | Y9: 27.44 | Z9: 16.8 | AA9: 0
B10: Arcillas Al | C10: 0.48 | D10: 1.1 | F10: 0 | G10: 0.1 | H10: 0 | I10: 0 | J10: 1.15 | K10: 0 | L10: 0 | M10: 0 | N10: 0.07 | O10: 0 | P10: 0 | Q10: 0 | R10: 0.88 | S10: 0 | T10: 0 | U10: 0 | V10: 0 | W10: 0 | X10: 0.36 | Y10: 0.08 | Z10: 1.65 | AA10: 0
B11: Plagioclasa | C11: 0 | D11: 1.05 | E11: 0.3 | F11: 0 | H11: 0 | I11: 0 | J11: 0 | K11: 0 | L11: 2.3 | M11: 0.3 | N11: 0.3 | O11: 0 | P11: 0 | Q11: 0 | R11: 0 | S11: 0 | T11: 0 | U11: 0 | V11: 0 | W11: 0 | X11: 0.28 | Y11: 0 | Z11: 0.34 | AA11: 0
B12: Piroxeno | C12: 0 | D12: 0 | E12: 0 | F12: 0 | G12: 0 | I12: 0 | J12: 0 | K12: 0 | L12: 0 | M12: 0 | N12: 0.02 | O12: 0 | P12: 0 | Q12: 0 | R12: 0 | S12: 0 | T12: 0 | U12: 0 | V12: 0 | W12: 0 | X12: 0.11 | Y12: 0 | Z12: 0 | AA12: 0
B13: Hematita/Magnetita | C13: 0 | D13: 0 | E13: 0.02 | F13: 0 | G13: 0 | H13: 0 | I13: 0 | K13: 0 | L13: 0 | M13: 0 | N13: 0.01 | O13: 0 | P13: 0 | Q13: 0 | R13: 0 | S13: 0 | T13: 0 | U13: 0 | V13: 0 | W13: 0 | X13: 0 | Y13: 0 | Z13: 0 | AA13: 0
B14: Anfibol | C14: 0 | D14: 0 | E14: 0 | F14: 0 | G14: 0.01 | H14: 0 | I14: 0 | J14: 0 | K14: 0 | M14: 0.65 | N14: 0 | O14: 0 | P14: 0 | Q14: 0 | R14: 0 | S14: 0 | T14: 0 | U14: 0 | V14: 0 | W14: 0 | X14: 0 | Y14: 0 | Z14: 0 | AA14: 0
B15: Biotita/flogopita | C15: 0 | D15: 0.02 | E15: 0 | F15: 0 | G15: 0.08 | H15: 0 | I15: 0 | J15: 0 | K15: 0 | L15: 3.62 | N15: 0.71 | O15: 0 | P15: 0 | Q15: 0 | R15: 0 | S15: 0 | T15: 0 | U15: 0 | V15: 0 | W15: 0 | X15: 0.01 | Y15: 0 | Z15: 0 | AA15: 0
B16: Clorita | C16: 0 | D16: 0.38 | E16: 0.08 | F16: 0 | G16: 0.38 | H16: 0.69 | I16: 0 | J16: 4.36 | K16: 0 | L16: 0 | M16: 0.75 | O16: 12.87 | P16: 0 | Q16: 0 | R16: 0 | S16: 0 | T16: 3.59 | U16: 0 | V16: 3 | W16: 0 | X16: 0.31 | Y16: 0 | Z16: 0 | AA16: 0
B17: Bornita | C17: 0 | D17: 0 | E17: 0 | F17: 0 | G17: 0 | H17: 0 | I17: 0 | J17: 0 | K17: 0 | L17: 0 | M17: 0 | N17: 0.02 | P17: 0 | Q17: 0 | R17: 0 | S17: 0 | T17: 0 | U17: 0 | V17: 0 | W17: 0.14 | X17: 0 | Y17: 0 | Z17: 1.94 | AA17: 0.71
B18: Calcosina/digenita | C18: 0 | D18: 0 | E18: 0 | F18: 0 | G18: 0 | H18: 0 | I18: 0 | J18: 0 | K18: 0 | L18: 0 | M18: 0 | N18: 0 | O18: 0 | Q18: 0 | R18: 0 | S18: 0 | T18: 0 | U18: 0 | V18: 0 | W18: 0 | X18: 0 | Y18: 0 | Z18: 0 | AA18: 3.64
B19: Enargita/Tennantita | C19: 0 | D19: 0 | E19: 0 | F19: 0 | G19: 0 | H19: 0 | I19: 0 | J19: 0 | K19: 0 | L19: 0 | M19: 0 | N19: 0 | O19: 0 | P19: 0 | R19: 0 | S19: 0 | T19: 0 | U19: 0 | V19: 0 | W19: 0.31 | X19: 0 | Y19: 0 | Z19: 0 | AA19: 3.17
B20: Alunita | C20: 0 | D20: 0.02 | E20: 0.34 | F20: 0 | G20: 0 | H20: 0 | I20: 0 | J20: 0 | K20: 0 | L20: 0 | M20: 0 | N20: 0 | O20: 0 | P20: 0 | Q20: 0 | S20: 0 | T20: 0 | U20: 0 | V20: 0 | W20: 0 | X20: 0.17 | Y20: 0 | Z20: 0 | AA20: 0
B21: Apatito | C21: 0 | D21: 0.01 | E21: 0 | F21: 0 | G21: 0 | H21: 0 | I21: 0 | J21: 0 | K21: 0 | L21: 0 | M21: 0 | N21: 0.05 | O21: 0 | P21: 0 | Q21: 0 | R21: 0 | S21: 0 | U21: 0 | V21: 0 | W21: 0 | X21: 0 | Y21: 0 | Z21: 0 | AA21: 0
B22: Ilmenita | C22: 0 | D22: 0.05 | E22: 0 | F22: 0 | G22: 0 | H22: 0 | I22: 0 | J22: 0 | K22: 0 | L22: 0 | M22: 0 | N22: 0.38 | O22: 0 | P22: 0 | Q22: 0 | R22: 0 | S22: 0 | T22: 0 | U22: 0 | W22: 0 | X22: 0 | Y22: 0 | Z22: 0 | AA22: 0
B23: Calcopirita | C23: 0 | D23: 0.67 | E23: 0 | F23: 0 | G23: 0 | H23: 0 | I23: 0 | J23: 0 | K23: 0 | L23: 0 | M23: 0 | N23: 0 | O23: 1.36 | P23: 0 | Q23: 3.33 | R23: 0 | S23: 0 | T23: 0 | U23: 0 | V23: 0 | X23: 0.43 | Y23: 0.59 | Z23: 8.86 | AA23: 0.47
B24: Cuarzo | C24: 1.69 | D24: 40.78 | E24: 4.44 | F24: 0 | G24: 2.28 | H24: 2.68 | I24: 0 | J24: 3.67 | K24: 0 | L24: 0 | M24: 2.25 | N24: 1.07 | O24: 0 | P24: 15.27 | Q24: 2.66 | R24: 6.53 | S24: 0 | T24: 0 | U24: 0 | V24: 0 | W24: 1.14 | Y24: 0.34 | Z24: 2.3 | AA24: 0.35
B25: Rutilo/anatase | C25: 0 | D25: 1.19 | E25: 3.36 | F25: 0 | G25: 0 | H25: 0 | I25: 0 | J25: 0 | K25: 0 | L25: 0 | M25: 0 | N25: 0 | O25: 0 | P25: 0 | Q25: 0 | R25: 0 | S25: 0 | T25: 0 | U25: 0 | V25: 0 | W25: 0.47 | X25: 0.01 | Z25: 0 | AA25: 0
B26: Pirita | C26: 0 | D26: 0.41 | E26: 0.03 | F26: 0 | G26: 0.03 | H26: 0 | I26: 0 | J26: 0 | K26: 0 | L26: 0 | M26: 0 | N26: 0 | O26: 0.54 | P26: 0 | Q26: 0 | R26: 0 | S26: 0 | T26: 0 | U26: 0 | V26: 0 | W26: 1.26 | X26: 0.03 | Y26: 0 | AA26: 0
B27: Covelina | C27: 0 | D27: 0 | E27: 0 | F27: 0 | G27: 0 | H27: 0 | I27: 0 | J27: 0 | K27: 0 | L27: 0 | M27: 0 | N27: 0 | O27: 0.39 | P27: 3.92 | Q27: 2 | R27: 0 | S27: 0 | T27: 0 | U27: 0 | V27: 0 | W27: 0.02 | X27: 0 | Y27: 0 | Z27: 0
B28: Otros | C28: 0.01 | D28: 0.35 | E28: 0.01 | F28: 0 | G28: 0 | H28: 0 | I28: 0 | J28: 0 | K28: 0 | L28: 0 | M28: 0 | N28: 0 | O28: 0 | P28: 0 | Q28: 0 | R28: 0 | S28: 0 | T28: 0 | U28: 0 | V28: 0 | W28: 0.07 | X28: 0.14 | Y28: 0.01 | Z28: 2.61 | AA28: 0
B29: Partículas complejas | C29: 88.14 | D29: 29.02 | E29: 66.39 | F29: 85.71 | G29: 73.2 | H29: 95.82 | I29: 0 | J29: 51.95 | K29: 100 | L29: 91.98 | M29: 82.94 | N29: 83.39 | O29: 67.05 | P29: 25.49 | Q29: 69.21 | R29: 33.62 | S29: 0 | T29: 58.63 | U29: 0 | V29: 85.58 | W29: 41.71 | X29: 23.3 | Y29: 40.78 | Z29: 32.77 | AA29: 39.37
B30: Total | C30: 100 | D30: 100 | E30: 100 | F30: 100 | G30: 100 | H30: 100 | I30: 100 | J30: 100 | K30: 100 | L30: 100 | M30: 100 | N30: 100 | O30: 100 | P30: 100 | Q30: 100 | R30: 100 | S30: 100 | T30: 100 | U30: 0 | V30: 100 | W30: 100 | X30: 100 | Y30: 100 | Z30: 100 | AA30: 100
B31: Complex/Other | C31: 3.0394587 | D31: 8.2155206 | E31: 2.5146456 | F31: 5.5570135 | G31: 5.6698778 | H31: 10.803139 | I31: 5.6257242 | J31: 1.286726 | K31: 2.8295505 | L31: 10.224849 | M31: 5.1643226

Sheet 10. Test Ciclo Abierto
B2: Test de Ciclo Abierto (TCA)
J4: Reactivos en g/t | N4: Concentrado | P4: Relave
B5: Etapa | C5: Vol. Celda, L | D5: Agitación, rpm | E5: Flujo Aire, L/min | F5: pH | G5: ORP, mV | H5: Tiempo Flot., mm;ss | I5: Frecuencia de Paleteo | J5: Matcol 715 | K5: FP-650 | L5: Matcol 660 | M5: Cal | N5: Peso Pulpa, g | O5: ID Bandeja | P5: Peso Pulpa, g | Q5: ID Bandeja | R5: ID Celda | S5: ml Cal 10%
B6: Grind | C6: - | D6: - | E6: - | F6: 8.4 | G6: 82.9 | H6: 14:40 | I6: - | J6: 28 | M6: 300 | N6: - | O6: - | P6: - | Q6: - | R6: - | S6: -
B7: Acond. | C7: 4.7 | D7: 1200 | E7: - | F7: 10.21 | G7: 38.8 | H7: 3:00 | I7: - | K7: 16 | N7: - | O7: - | P7: - | Q7: - | S7: 3.2
B8: Rougherx2 | C8: 4.7 | D8: 1200 | E8: 10 | F8: 10.22 | G8: 39.2 | H8: 20:00 | I8: 1 cada 10 sg | K8: 8 | N8: 3417.7 | O8: B018 | P8: 7420.6 | Q8: - | R8: C-42 | S8: 2.6
B9: Regrind | C9: - | D9: - | E9: - | F9: 11.38 | G9: 79.7 | H9: 00:30 | I9: - | M9: 500 | O9: - | P9: - | Q9: - | R9: - | S9: -
B10: Cleaner 1 | C10: 3 | D10: 1200 | E10: 2 | F10: 11.3 | G10: 51.6 | H10: 3:00 | I10: 1 cada 15 sg | L10: 6 | N10: 632.8 | O10: F077 | P10: - | Q10: - | R10: C-13 | S10: 0
B11: Cleaner Scv | C11: 3 | D11: 1200 | E11: 6 | F11: 11.32 | G11: 19.6 | H11: 15:00 | I11: 1 cada 5 sg | N11: 2099 | O11: B088 | P11: 4828.5 | Q11: TK-43 | R11: C-13 | S11: 6.2
B12: Cleaner 2 | C12: 1.3 | D12: 800 | E12: 1.5 | F12: 11.34 | G12: -5.3 | H12: 3:00 | I12: 1 cada 15 sg | N12: 486.7 | O12: F131 | P12: 2336.6 | Q12: F097 | R12: B | S12: 1.2
B14: Producto | C14: Peso | E14: Análisis Químicos%
C15: g | D15: % | E15: Cu-T | F15: Mo | G15: Fe | H15: S
B16: Relave Ro | C16: 2922.7 | E16: 0.09 | F16: 38 | G16: 1.533 | H16: 1.15
B17: Concentrado 1°CL | C17: 69.2 | E17: 17.5 | F17: 1375 | G17: 19.77 | H17: 25.21
B18: Relave Cln SCV | C18: 361 | E18: 0.142 | F18: 178 | G18: 1.969 | H18: 1.61
B19: Relave 2 Cl | C19: 105.8 | E19: 2.27 | F19: 725 | G19: 5.398 | H19: 5.96
B20: Concentrado 2°Cl | C20: 35 | E20: 14.98 | F20: 1751 | G20: 21.1 | H20: 24.01
B22: Alimentación Cl. Assay | C22: - | E22: 3.57 | F22: 479.6 | G22: 6.24 | H22: 7.36
B25: Balance
E27: % | J27: gr
D28: Peso, gr | E28: =E15 -> Cu-T | F28: =F15 -> Mo | G28: =G15 -> Fe | H28: =H15 -> S | J28: =E28 -> Cu-T | K28: =F28 -> Mo | L28: =G28 -> Fe | M28: =H28 -> S
C29: alim | D29: =D30+D31 -> 3493.7 | E29: =J29*100/$D29 -> 0.65540001 | F29: =K29*100/$D29 -> 116.91347 | G29: =L29*100/$D29 -> 2.2523401 | H29: =M29*100/$D29 -> 2.0487635 | J29: =SUM(J30:J31) -> 22.89771 | K29: =SUM(K30:K31) -> 4084.606 | L29: =SUM(L30:L31) -> 78.690005 | M29: =SUM(M30:M31) -> 71.57765
B30: Rougher | C30: conc | D30: =D35 -> 571 | E30: =E35 -> 3.5494361 | F30: =F35 -> 520.83713 | G30: =G35 -> 5.9343282 | H30: =H35 -> 6.6491419 | J30: =E30*$D30/100 -> 20.26728 | K30: =F30*$D30/100 -> 2973.98 | L30: =G30*$D30/100 -> 33.885014 | M30: =H30*$D30/100 -> 37.9666
C31: relave | D31: =C16 -> 2922.7 | E31: =E16 -> 0.09 | F31: =F16 -> 38 | G31: =G16 -> 1.533 | H31: =H16 -> 1.15 | J31: =E31*$D31/100 -> 2.63043 | K31: =F31*$D31/100 -> 1110.626 | L31: =G31*$D31/100 -> 44.804991 | M31: =H31*$D31/100 -> 33.61105
C32: alim | D32: =D33+D34 -> 501.8 | E32: =J32*100/$D32 -> 1.6256038 | F32: =K32*100/$D32 -> 403.04504 | G32: =L32*100/$D32 -> 4.02634 | H32: =M32*100/$D32 -> 4.0895337 | J32: =SUM(J33:J34) -> 8.15728 | K32: =SUM(K33:K34) -> 2022.48 | L32: =SUM(L33:L34) -> 20.204174 | M32: =SUM(M33:M34) -> 20.52128
B33: Scavenger | C33: conc | D33: =D38 -> 140.8 | E33: =E38 -> 5.429446 | F33: =F38 -> 980.04261 | G33: =G38 -> 9.301196 | H33: =H38 -> 10.446861 | J33: =E33*$D33/100 -> 7.64466 | K33: =F33*$D33/100 -> 1379.9 | L33: =G33*$D33/100 -> 13.096084 | M33: =H33*$D33/100 -> 14.70918
C34: relave | D34: =C18 -> 361 | E34: =E18 -> 0.142 | F34: =F18 -> 178 | G34: =G18 -> 1.969 | H34: =H18 -> 1.61 | J34: =E34*$D34/100 -> 0.51262 | K34: =F34*$D34/100 -> 642.58 | L34: =G34*$D34/100 -> 7.10809 | M34: =H34*$D34/100 -> 5.8121
C35: alim | D35: =D36+D37 -> 571 | E35: =J35*100/$D35 -> 3.5494361 | F35: =K35*100/$D35 -> 520.83713 | G35: =L35*100/$D35 -> 5.9343282 | H35: =M35*100/$D35 -> 6.6491419 | J35: =SUM(J36:J37) -> 20.26728 | K35: =SUM(K36:K37) -> 2973.98 | L35: =SUM(L36:L37) -> 33.885014 | M35: =SUM(M36:M37) -> 37.9666
B36: Cleaner 1 | C36: conc | D36: =C17 -> 69.2 | E36: =E17 -> 17.5 | F36: =F17 -> 1375 | G36: =G17 -> 19.77 | H36: =H17 -> 25.21 | J36: =E36*$D36/100 -> 12.11 | K36: =F36*$D36/100 -> 951.5 | L36: =G36*$D36/100 -> 13.68084 | M36: =H36*$D36/100 -> 17.44532
C37: relave | D37: =D32 -> 501.8 | E37: =E32 -> 1.6256038 | F37: =F32 -> 403.04504 | G37: =G32 -> 4.02634 | H37: =H32 -> 4.0895337 | J37: =E37*$D37/100 -> 8.15728 | K37: =F37*$D37/100 -> 2022.48 | L37: =G37*$D37/100 -> 20.204174 | M37: =H37*$D37/100 -> 20.52128
C38: alim | D38: =D39+D40 -> 140.8 | E38: =J38*100/$D38 -> 5.429446 | F38: =K38*100/$D38 -> 980.04261 | G38: =L38*100/$D38 -> 9.301196 | H38: =M38*100/$D38 -> 10.446861 | J38: =SUM(J39:J40) -> 7.64466 | K38: =SUM(K39:K40) -> 1379.9 | L38: =SUM(L39:L40) -> 13.096084 | M38: =SUM(M39:M40) -> 14.70918
B39: Cleaner 2 | C39: conc | D39: =C20 -> 35 | E39: =E20 -> 14.98 | F39: =F20 -> 1751 | G39: =G20 -> 21.1 | H39: =H20 -> 24.01 | J39: =E39*$D39/100 -> 5.243 | K39: =F39*$D39/100 -> 612.85 | L39: =G39*$D39/100 -> 7.385 | M39: =H39*$D39/100 -> 8.4035
C40: relave | D40: =C19 -> 105.8 | E40: =E19 -> 2.27 | F40: =F19 -> 725 | G40: =G19 -> 5.398 | H40: =H19 -> 5.96 | J40: =E40*$D40/100 -> 2.40166 | K40: =F40*$D40/100 -> 767.05 | L40: =G40*$D40/100 -> 5.711084 | M40: =H40*$D40/100 -> 6.30568
B42: Recuperación por Etapa | C42: =B30 -> Rougher | D42: =D30/D29 -> 0.16343704 | E42: =J30/J29 -> 0.88512257 | F42: =K30/K29 -> 0.7280947 | G42: =L30/L29 -> 0.43061395 | H42: =M30/M29 -> 0.53042535
C43: =B33 -> Scavenger | D43: =D33/D32 -> 0.28058988 | E43: =J33/J32 -> 0.93715797 | F43: =K33/K32 -> 0.68228116 | G43: =L33/L32 -> 0.64818705 | H43: =M33/M32 -> 0.71677693
C44: =B36 -> Cleaner 1 | D44: =D36/D35 -> 0.12119089 | E44: =J36/J35 -> 0.59751481 | F44: =K36/K35 -> 0.31994163 | G44: =L36/L35 -> 0.40374308 | H44: =M36/M35 -> 0.45949124
C45: =B39 -> Cleaner 2 | D45: =D39/D38 -> 0.24857955 | E45: =J39/J38 -> 0.68583822 | F45: =K39/K38 -> 0.44412639 | G45: =L39/L38 -> 0.56390903 | H45: =M39/M38 -> 0.57130989
B47: Recuperación Global | C47: Rougher | D47: =D42 -> 0.16343704 | E47: =E42 -> 0.88512257 | F47: =F42 -> 0.7280947 | G47: =G42 -> 0.43061395 | H47: =H42 -> 0.53042535
C48: Cleaner | D48: =(D30-D34)/D30 -> 0.36777583 | E48: =(J30-J34)/J30 -> 0.97470702 | F48: =(K30-K34)/K30 -> 0.78393264 | G48: =(L30-L34)/L30 -> 0.7902291 | H48: =(M30-M34)/M30 -> 0.84691545
C49: Global | D49: =+D48*D47 -> 0.060108195 | E49: =+E48*E47 -> 0.86273518 | F49: =+F48*F47 -> 0.57077721 | G49: =+G48*G47 -> 0.34028367 | H49: =+H47*H48 -> 0.44922542
...

Sheet 11. Casos
B2: # | C2: Casos Piloto Jameson | D2: Hipótesis a validar
B3: 1 | C3: Caso Base (con compósito) | D3: Establecer el circuito base con condiciones actuales de planta LS2 de comparación para los siguientes casos
B4: 2 | C4: Caso Base (con compósito) + Jameson [Cola Ro] | D4: Cuantificar potencial recuperación y ley de cobre en relave rougher que actualmente se va directo a relave final
B5: 3 | C5: Caso Base (con compósito)+ Jameson [Pre Cl-SCV] | D5: Cuantificar el impacto en la recuperación y ley de cobre en relave 1ra limpieza al disminuir la alimentación y recirculación de finos en la etapa scavenger-cleaner del circuito
B6: 4 | C6: Caso Base (con compósito)+ Jameson [Pre-Cl] | D6: Cuantificar el impacto en la 1ra flotación de limpieza al disminuir la alimentación y recirculación de finos en esta parte del circuito
B7: 5 | C7: Mayor Flujo Caso Base (con compósito) + Jameson [Pre Cl-SCV] | D7: Cuantificar el impacto del throughput en el performance obtenido en la prueba del caso N°3
B8: 6 | C8: Caso Base (con compósito) P80 mayor + Jameson [Cola Ro] | D8: Cuantificar el impacto del P80 en el performance obtenido en la prueba del caso N°2. Además, obtener resultados complementarios por su a futuro se pretende aumentar el P80 en planta
B9: 7 | C9: Caso Base (con compósito) + Dispersante | D9: Establecer el impacto del dispersante en el caso base del piloto
B10: 8 | C10: Caso Base con Muestra alta ley | D10: Establecer el caso base para periodos donde la ley de alimentación en planta aumente y cuantificar el impacto de la ley con respecto al circuito base con compósito
B11: 9 | C11: Caso Base con Muestra baja ley | D11: Establecer el caso base para periodos donde la ley de alimentación en planta disminuya y cuantificar el impacto de la ley con respecto al circuito base con compósito
B12: 10 | C12: Mejor Caso Jameson (con compósito) + Dispersante | D12: Establecer el impacto del dispersante en el mejor caso con Jameson elegido (Caso N°2, N°3, N°4)

Sheet 12. Circuitos
B2: Circuitos
S28: P80 = 165 um
S29: P80 = 180 um

Sheet 13. Pilotaje Rougher
B2: Pilotaje Rougher
B4: Parámetros | C4: #1 - Caso Base Original | D4: #2 - Caso Base Original Mejorado | E4: #3 – Caso Base Original Mejorado con Aire
B5: pH | C5: 10.2 | D5: 9.6 | E5: 9.6
B6: NaSH | C6: No | D6: Sí (ORP ≈ -125) | E6: Sí (ORP ≈ -125)
B7: Feed P80 (µm) | C7: 165 | D7: 165 | E7: 165
B8: %Cp | C8: 0.3 | D8: 0.3 | E8: 0.3
B9: Collector Matcol715 (g/ton) | C9: 28 | D9: 28 | E9: 28
B10: Frother FP-650 (g/ton) | C10: 16–18 | D10: 16–18 | E10: 18–24
B11: Aire (Jg) | C11: Normal (0.4–0.5) | D11: Normal (0.4–0.5) | E11: Aumentado (0.7-1.0)
B12: %Cu Alimentación | C12: 0.665 | D12: 0.666 | E12: 0.663
B13: %Cu Concentrado | C13: 5.413 | D13: 3.643 | E13: 3.03
B14: %Cu Cola | C14: 0.157 | D14: 0.139 | E14: 0.128
B15: %Cu Recuperación | C15: 78.9 | D15: 82.5 | E15: 84.7
B16: %Cu Recuperación en Peso | C16: 10.764 | D16: 15.97 | E16: 18.136
B18: Fecha | C18: Condición | D18: P80 | E18: Elemento | F18: Alim. Ro | G18: Cola Ro | H18: Conc. Ro | I18: Rec. Másica (%) | J18: RE Rougher | K18: Rec. Met. % | L18: Elemento | M18: Alim. Ro | N18: Cola Ro | O18: Conc. Ro | P18: Rec. Masica (%) | Q18: RE Rougher | R18: Rec. Met. %
B19: Estándar | C19: Estándar | D19: 165 | E19: Cu | F19: 0.65 | G19: 0.1 | H19: 4.46 | I19: =+'17. Jms - Pre Rougher'!M38 -> 12.537734 | J19: 6.8615385 | K19: 86.345467 | L19: Fe | M19: 1.95 | N19: 1.22 | O19: 7.08 | P19: =+'17. Jms - Pre Rougher'!M38 -> 12.537734 | Q19: =+O19/M19 -> 3.6307692 | R19: =+'17. Jms - Pre Rougher'!P38 -> 45.418572
B20: 04-08-2025 | C20: Cond. 1 | D20: 165 | E20: Cu | F20: 0.609 | G20: 0.167 | H20: 2.083 | I20: 23.068894 | J20: 3.4203612 | K20: 78.903949 | L20: Fe | M20: 1.87 | N20: 1.6 | O20: 3.35 | P20: 15.428571 | Q20: 1.7914439 | R20: 27.639419
B21: 04-08-2025 | C21: Cond. 1 | D21: 165 | E21: Cu | F21: 0.638 | G21: 0.124 | H21: 3.415 | I21: 15.618353 | J21: 5.3526646 | K21: 83.599805 | L21: Fe | M21: 2.11 | N21: 1.43 | O21: 5.36 | P21: 17.302799 | Q21: 2.5402844 | R21: 43.95403
B22: 05-08-2025 | C22: Cond. 1 | D22: 165 | E22: Cu | F22: 0.646 | G22: 0.128 | H22: 3.629 | I22: 14.795773 | J22: 5.6176471 | K22: 83.117429 | L22: Fe | M22: 2.24 | N22: 1.26 | O22: 7.66 | P22: 15.3125 | Q22: 3.4196429 | R22: 52.363281
B23: 05-08-2025 | C23: Cond. 1 | D23: 165 | E23: Cu | F23: 0.634 | G23: 0.15 | H23: 6.22 | I23: 7.9736409 | J23: 9.8107256 | K23: 78.227202 | L23: Fe | M23: 2.4 | N23: 1.7 | O23: 9.12 | P23: 9.4339623 | Q23: 3.8 | R23: 35.849057
B24: 06-08-2025 | C24: Cond. 1 | D24: 165 | E24: Cu | F24: 0.711 | G24: 0.15 | H24: 5.55 | I24: 10.388889 | J24: 7.8059072 | K24: 81.094702 | L24: Fe | M24: 2.33 | N24: 1.52 | O24: 8.21 | P24: 12.107623 | Q24: 3.5236052 | R24: 42.662484
B25: 06-08-2025 | C25: Cond. 1 | D25: 165 | E25: Cu | F25: 0.681 | G25: 0.146 | H25: 7.48 | I25: 7.2947914 | J25: 10.983847 | K25: 80.124875 | L25: Fe | M25: 2.47 | N25: 1.84 | O25: 12.4 | P25: 5.9659091 | Q25: 5.0202429 | R25: 29.950313
B26: 07-08-2025 | C26: Cond. 1 | D26: 165 | E26: Cu | F26: 0.703 | G26: 0.154 | H26: 5.01 | I26: 11.305601 | J26: 7.1266003 | K26: 80.570502 | L26: Fe | M26: 2.32 | N26: 1.73 | O26: 6.94 | P26: 11.324376 | Q26: 2.9913793 | R26: 33.875505
B27: 07-08-2025 | C27: Cond. 1 | D27: 165 | E27: Cu | F27: 0.691 | G27: 0.145 | H27: 6.09 | I27: 9.1841884 | J27: 8.813314 | K27: 80.943136 | L27: Fe | M27: 2.5 | N27: 1.9 | O27: 8.16 | P27: 9.5846645 | Q27: 3.264 | R27: 31.284345
B28: 11-08-2025 | C28: Cond. 1 | D28: 165 | E28: Cu | F28: 0.714 | G28: 0.155 | H28: 5.91 | I28: 9.7132928 | J28: 8.2773109 | K28: 80.399945 | L28: Fe | M28: 2.33 | N28: 1.73 | O28: 8.07 | P28: 9.4637224 | Q28: 3.4635193 | R28: 32.777785
B29: 11-08-2025 | C29: Cond. 1 | D29: 165 | E29: Cu | F29: 0.691 | G29: 0.165 | H29: 2.984 | I29: 18.659099 | J29: 4.3183792 | K29: 80.577064 | L29: Fe | M29: 2.33 | N29: 1.82 | O29: 4.27 | P29: 20.816327 | Q29: 1.832618 | R29: 38.148375
B30: 12-08-2025 | C30: Cond. 1 | D30: 165 | E30: Cu | F30: 0.676 | G30: 0.183 | H30: 6.22 | I30: 8.1663078 | J30: 9.2011834 | K30: 75.139696 | L30: Fe | M30: 2.43 | N30: 1.82 | O30: 9.22 | P30: 8.2432432 | Q30: 3.7942387 | R30: 31.276832
B31: 12-08-2025 | C31: Cond. 1 | D31: 165 | E31: Cu | F31: 0.698 | G31: 0.161 | H31: 6.02 | I31: 9.1653866 | J31: 8.6246418 | K31: 79.048177 | L31: Fe | M31: 2.28 | N31: 1.72 | O31: 8.77 | P31: 7.9432624 | Q31: 3.8464912 | R31: 30.553689
... B52: 28-08-2025 | C52: Cond. 2 | D52: 165 | E52: Cu | F52: 0.687 | G52: 0.146 | H52: 3.745 | I52: 15.031953 | J52: 5.4512373 | K52: 81.942744 | L52: Fe | M52: 2.41 | N52: 1.11 | O52: 10.7 | P52: 13.555787 | Q52: 4.439834 | R52: 60.185446
M53: =AVERAGE(M37:M52) -> 2.35625 | N53: =AVERAGE(N37:N52) -> 1.016875 | O53: =AVERAGE(O37:O52) -> 9.62375
E54: Cond #1 | F54: =+AVERAGE(F20:F36) -> 0.67582353 | G54: =+AVERAGE(G20:G36) -> 0.15441176
E55: Cond #2 | F55: =+AVERAGE(F37:F52) -> 0.6816875 | G55: =+AVERAGE(G37:G52) -> 0.1315
C56: Alim. Ro | D56: Cola Ro | E56: Conc. Ro | M56: Alim. Ro | N56: Cola Ro | O56: Conc. Ro
B57: CV #1 | C57: =_xlfn.STDEV.S(F20:F36)/AVERAGE(F20:F36) -> 0.042333467 | D57: =_xlfn.STDEV.S(G20:G36)/AVERAGE(G20:G36) -> 0.13522797 | E57: =_xlfn.STDEV.S(H20:H36)/AVERAGE(H20:H36) -> 0.31349348 | L57: CV #1 | M57: =_xlfn.STDEV.S(M20:M36)/AVERAGE(M20:M36) -> 0.064045984 | N57: =_xlfn.STDEV.S(N20:N36)/AVERAGE(N20:N36) -> 0.17031428 | O57: =_xlfn.STDEV.S(O20:O36)/AVERAGE(O20:O36) -> 0.26969942
B58: CV #2 | C58: =_xlfn.STDEV.S(F37:F52)/AVERAGE(F37:F52) -> 0.015354852 | D58: =_xlfn.STDEV.S(G37:G52)/AVERAGE(G37:G52) -> 0.081384218 | E58: =_xlfn.STDEV.S(H37:H52)/AVERAGE(H37:H52) -> 0.25324323 | L58: CV #2 | M58: =_xlfn.STDEV.S(M37:M52)/AVERAGE(M37:M52) -> 0.018196622 | N58: =_xlfn.STDEV.S(N37:N52)/AVERAGE(N37:N52) -> 0.082177109 | O58: =_xlfn.STDEV.S(O37:O52)/AVERAGE(O37:O52) -> 0.30651462
B59: Media #1 | E59: =AVERAGE(H20:H36) -> 5.1583529
B60: Media #2 | E60: =+AVERAGE(H37:H52) -> 3.21325
B61: Desv #1 | E61: =+_xlfn.STDEV.S(H20:H36) -> 1.61711 | M61: Condición #1 | N61: Condición #2
B62: Desv #2 | E62: =_xlfn.STDEV.S(H37:H52) -> 0.81373382 | L62: Mínimo | M62: =+MIN(R20:R36) -> 19.942537 | N62: =+MIN(R37:R52) -> 56.804432
B63: Rango #1 | E63: =E59+2*E61 -> 8.392573 | F63: =E59-2*E61 -> 1.9241329 | L63: Máximo | M63: =+MAX(R20:R36) -> 67.203583 | N63: =+MAX(R37:R52) -> 69.346172
...

Sheet 14. Cinética Rougher
B2: Cinéticas Rougher
B3: P80 165 um
B5: Cinetica STD | C5: Tiempo, min | D5: Tiempo acumulado, min | E5: Masa seca, gr | F5: Masa húmeda, gr | G5: Cp, % | H5: Masa acumulada, gr | I5: Ley, Cu% | J5: Ley acumulada, Cu% | K5: Recuperación, Cu% | L5: Mass Pull, % | M5: Mass Pull acumulado, % | N5: Ley, Fe% | O5: Ley acumulada, Fe% | P5: Recuperación, Fe%
B6: Concentrado 1 | C6: 0.5 | D6: =+C6 -> 0.5 | E6: 13.125368 | G6: =+E6/F6*100 -> #DIV/0! | H6: =E6 -> 13.125368 | I6: 10.99 | J6: =SUMPRODUCT(E6,I6)/H6 -> 10.99 | K6: =SUMPRODUCT(H6,J6)/SUMPRODUCT($H$11,$J$11)*100 -> 35.531947 | L6: =E6/$E$12*100 -> 2.0950593 | M6: =+L6 -> 2.0950593 | N6: 13.1 | O6: =SUMPRODUCT(E6,N6)/H6 -> 13.1 | P6: =SUMPRODUCT(M6,O6)/SUMPRODUCT($M$11,$O$11)*100 -> 10.717802
B7: Concentrado 2 | C7: 1 | D7: =+D6+C7 -> 1.5 | E7: 14.000173 | G7: =+E7/F7*100 -> #DIV/0! | H7: =H6+E7 -> 27.125541 | I7: 3.454 | J7: =SUMPRODUCT(E6:E7,I6:I7)/H7 -> 7.1004812 | K7: =SUMPRODUCT(H7,J7)/SUMPRODUCT($H$11,$J$11)*100 -> 47.443422 | L7: =E7/$E$12*100 -> 2.2346948 | M7: =+M6+L7 -> 4.3297541 | N7: 5.54 | O7: =SUMPRODUCT(E6:E7,N6:N7)/H7 -> 9.1980942 | P7: =SUMPRODUCT(M7,O7)/SUMPRODUCT($M$11,$O$11)*100 -> 15.552463
B8: Concentrado 3 | C8: 2 | D8: =+D7+C8 -> 3.5 | E8: 23.634593 | G8: =+E8/F8*100 -> #DIV/0! | H8: =H7+E8 -> 50.760134 | I8: 1.662 | J8: =SUMPRODUCT(E6:E8,I6:I8)/H8 -> 4.5682521 | K8: =SUMPRODUCT(H8,J8)/SUMPRODUCT($H$11,$J$11)*100 -> 57.119268 | L8: =E8/$E$12*100 -> 3.7725322 | M8: =+M7+L8 -> 8.1022863 | N8: 3.6 | O8: =SUMPRODUCT(E6:E8,N6:N8)/H8 -> 6.5915471 | P8: =SUMPRODUCT(M8,O8)/SUMPRODUCT($M$11,$O$11)*100 -> 20.856098
B9: Concentrado 4 | C9: 8 | D9: =+D8+C9 -> 11.5 | E9: 84.148063 | G9: =+E9/F9*100 -> #DIV/0! | H9: =H8+E9 -> 134.9082 | I9: 1.119 | J9: =SUMPRODUCT(E6:E9,I6:I9)/H9 -> 2.4168047 | K9: =SUMPRODUCT(H9,J9)/SUMPRODUCT($H$11,$J$11)*100 -> 80.313716 | L9: =E9/$E$12*100 -> 13.431637 | M9: =+M8+L9 -> 21.533923 | N9: 3.85 | O9: =SUMPRODUCT(E6:E9,N6:N9)/H9 -> 4.8815259 | P9: =SUMPRODUCT(M9,O9)/SUMPRODUCT($M$11,$O$11)*100 -> 41.05035
B10: Concentrado 5 | C10: 16 | D10: =+D9+C10 -> 27.5 | E10: 66.441015 | G10: =+E10/F10*100 -> #DIV/0! | H10: =H9+E10 -> 201.34921 | I10: 0.499 | J10: =SUMPRODUCT(E6:E10,I6:I10)/H10 -> 1.7839694 | K10: =SUMPRODUCT(H10,J10)/SUMPRODUCT($H$11,$J$11)*100 -> 88.480416 | L10: =E10/$E$12*100 -> 10.605254 | M10: =+M9+L10 -> 32.139177 | N10: 2.78 | O10: =SUMPRODUCT(E6:E10,N6:N10)/H10 -> 4.1880665 | P10: =SUMPRODUCT(M10,O10)/SUMPRODUCT($M$11,$O$11)*100 -> 52.56376
B11: Relave | E11: 425.14228 | G11: =+E11/F11*100 -> #DIV/0! | H11: =H10+E11 -> 626.4915 | I11: 0.11 | J11: =SUMPRODUCT(E5:E11,I5:I11)/H11 -> 0.648 | K11: =SUMPRODUCT(H11,J11)/SUMPRODUCT($H$11,$J$11)*100 -> 100 | L11: =E11/$E$12*100 -> 67.860823 | M11: =+M10+L11 -> 100 | N11: 1.79 | O11: =SUMPRODUCT(E5:E11,N5:N11)/H11 -> 2.5607188 | P11: =SUMPRODUCT(M11,O11)/SUMPRODUCT($M$11,$O$11)*100 -> 100
B12: Alimentación | E12: =+SUM(E6:E11) -> 626.4915 | G12: =+I12/F12*100 -> #DIV/0! | I12: =+SUMPRODUCT(I6:I11,E6:E11)/SUM(E6:E11) -> 0.648
B13: Cabeza Medida | I13: 0.648
B14: Cabeza Calculada | I14: =+(I12-I13)/I12 -> -1.4140697e-09 | J14: =+SUMPRODUCT(I6:I11,E6:E11)/SUM(E6:E11) -> 0.648
B15: Error | J15: =+(J13-J14)/J13 -> #DIV/0!
B18: P80 145 um
B20: Cinetica STD | C20: Tiempo, min | D20: Tiempo acumulado, min | E20: Masa seca, gr | F20: Masa húmeda, gr | G20: Cp, % | H20: Masa acumulada, gr | I20: Ley, Cu% | J20: Ley acumulada, Cu% | K20: Recuperación, Cu% | L20: Mass Pull, % | M20: Mass Pull acumulado, % | N20: Ley, Fe% | O20: Ley acumulada, Fe% | P20: Recuperación, Fe%
B21: Concentrado 1 | C21: 0.5 | D21: =+C21 -> 0.5 | E21: 15.861809 | G21: =+E21/F21*100 -> #DIV/0! | H21: =E21 -> 15.861809 | I21: 12.07 | J21: =SUMPRODUCT(E21,I21)/H21 -> 12.07 | K21: =SUMPRODUCT(H21,J21)/SUMPRODUCT($H$26,$J$26)*100 -> 36.872449 | L21: =E21/$E$27*100 -> 1.9795648 | M21: =+L21 -> 1.9795648 | N21: 14.4 | O21: =SUMPRODUCT(E21,N21)/H21 -> 14.4 | P21: =SUMPRODUCT(M21,O21)/SUMPRODUCT($M$26,$O$26)*100 -> 10.619023
B22: Concentrado 2 | C22: 1 | D22: =+D21+C22 -> 1.5 | E22: 12.819256 | G22: =+E22/F22*100 -> #DIV/0! | H22: =H21+E22 -> 28.681064 | I22: 6.46 | J22: =SUMPRODUCT(E21:E22,I21:I22)/H22 -> 9.5625608 | K22: =SUMPRODUCT(H22,J22)/SUMPRODUCT($H$26,$J$26)*100 -> 52.821592 | L22: =E22/$E$27*100 -> 1.5998521 | M22: =+M21+L22 -> 3.5794168 | N22: 9.52 | O22: =SUMPRODUCT(E21:E22,N21:N22)/H22 -> 12.218841 | P22: =SUMPRODUCT(M22,O22)/SUMPRODUCT($M$26,$O$26)*100 -> 16.292759
B23: Concentrado 3 | C23: 2 | D23: =+D22+C23 -> 3.5 | E23: 21.371006 | G23: =+E23/F23*100 -> #DIV/0! | H23: =H22+E23 -> 50.052071 | I23: 3.237 | J23: =SUMPRODUCT(E21:E23,I21:I23)/H23 -> 6.8617015 | K23: =SUMPRODUCT(H23,J23)/SUMPRODUCT($H$26,$J$26)*100 -> 66.144826 | L23: =E23/$E$27*100 -> 2.6671165 | M23: =+M22+L23 -> 6.2465334 | N23: 8.3 | O23: =SUMPRODUCT(E21:E23,N21:N23)/H23 -> 10.545592 | P23: =SUMPRODUCT(M23,O23)/SUMPRODUCT($M$26,$O$26)*100 -> 24.539312
B24: Concentrado 4 | C24: 8 | D24: =+D23+C24 -> 11.5 | E24: 60.705619 | G24: =+E24/F24*100 -> #DIV/0! | H24: =H23+E24 -> 110.75769 | I24: 1.364 | J24: =SUMPRODUCT(E21:E24,I21:I24)/H24 -> 3.8484446 | K24: =SUMPRODUCT(H24,J24)/SUMPRODUCT($H$26,$J$26)*100 -> 82.092057 | L24: =E24/$E$27*100 -> 7.5761037 | M24: =+M23+L24 -> 13.822637 | N24: 6.48 | O24: =SUMPRODUCT(E21:E24,N21:N24)/H24 -> 8.3172656 | P24: =SUMPRODUCT(M24,O24)/SUMPRODUCT($M$26,$O$26)*100 -> 42.827609
B25: Concentrado 5 | C25: 16 | D25: =+D24+C25 -> 27.5 | E25: 61.726783 | G25: =+E25/F25*100 -> #DIV/0! | H25: =H24+E25 -> 172.48447 | I25: 0.559 | J25: =SUMPRODUCT(E21:E25,I21:I25)/H25 -> 2.6712555 | K25: =SUMPRODUCT(H25,J25)/SUMPRODUCT($H$26,$J$26)*100 -> 88.737554 | L25: =E25/$E$27*100 -> 7.7035456 | M25: =+M24+L25 -> 21.526183 | N25: 3.42 | O25: =SUMPRODUCT(E21:E25,N21:N25)/H25 -> 6.5646878 | P25: =SUMPRODUCT(M25,O25)/SUMPRODUCT($M$26,$O$26)*100 -> 52.642131
